Workbook

Sheet L1 Info
A1: General Details / Installation Time
A2: Project NO. : | C2: DOC No.:
A3: Date: | B3: ____/___/_____ | C3: Serial NO. : | G3: Inputs
C4: REV NO. : | G4: Output
A6: Elevator General Data | C6: Value | D6: Remarks
A7: Elevator Name | C7: L1
A8: Total Height, m
A9: No. of Landing doors
A10: Number of shifts | D10: 1 OR 1.5
A11: Number of working day per Month | D11: 4 days off is mandatory safety wise for rest and relief
A12: No. of guiderails set (each set is 5m) | C12: =C8/5 -> 0 | D12: Each sets is consists of 2 CAR 5m guiderails, 2 CWT 5m guiderails, 3 brackets for each guiderails 12 by total
A13: No. of traction ropes | D13: The ropes quantity is drawn from motor specs
A15: Project Estimated time, working day | C15: Days | D15: Remarks
A16: Scaffolding | C16: =C8/(C10*20) -> #DIV/0! | D16: 20m per shift
A17: Jigs and nots
A18: Guiderails | C18: =(C8/(5*C10))+1 -> #DIV/0! | D18: 1 set per shift
A19: Motor and control panel | C19: =1.5/C10 -> #DIV/0! | D19: 1.5 shifts
A20: Cabin and counter weight frame (1.5 shifts) | C20: =1.5/C10 -> #DIV/0! | D20: 1.5 shifts
A21: Traction ropes | C21: =(2*C8*C13)/(C10*175) -> #DIV/0! | D21: 175m per shift
A22: First operating and inspection (1.5 shifts) | C22: =1.5/C10 -> #DIV/0! | D22: 1.5 shifts
A23: Landing doors | C23: =C9/C10 -> #DIV/0! | D23: 1 landing door per shift per day
A24: Vinyl and travel
A25: LOP place drilling
A26: Cabin Interior assembly
A27: Electrical equipment
A28: Testing and commissioning
A29: Estimated Working Days | C29: =SUM(C16:C28) -> #DIV/0!
A31: Duration of 1 elevator intallation by month | C31: =C29/C11 -> #DIV/0!
A32: Number of Teams
A33: Qty. of Elevators
A35: Duration of all Elevators intallation by months | C35: =C31*C33/C32 -> #DIV/0!

Sheet L2 Info
A1: General Details / Installation Time
A2: Project NO. : | C2: DOC No.:
A3: Date: | B3: ____/___/_____ | C3: Serial NO. : | G3: Inputs
C4: REV NO. : | G4: Output
A6: Elevator General Data | C6: Value | D6: Remarks
A7: Elevator Name | C7: L2
A8: Total Height, m
A9: No. of Landing doors
A10: Number of shifts | D10: 1 OR 1.5
A11: Number of working day per Month | D11: 4 days off is mandatory safety wise for rest and relief
A12: No. of guiderails set (each set is 5m) | C12: =C8/5 -> 0 | D12: Each sets is consists of 2 CAR 5m guiderails, 2 CWT 5m guiderails, 3 brackets for each guiderails 12 by total
A13: No. of traction ropes | D13: The ropes quantity is drawn from motor specs
A15: Project Estimated time, working day | C15: Days | D15: Remarks
A16: Scaffolding | C16: =C8/(C10*20) -> #DIV/0! | D16: 20m per shift
A17: Jigs and nots
A18: Guiderails | C18: =(C8/(5*C10))+1 -> #DIV/0! | D18: 1 set per shift
A19: Motor and control panel | C19: =1.5/C10 -> #DIV/0! | D19: 1.5 shifts
A20: Cabin and counter weight frame (1.5 shifts) | C20: =1.5/C10 -> #DIV/0! | D20: 1.5 shifts
A21: Traction ropes | C21: =(2*C8*C13)/(C10*175) -> #DIV/0! | D21: 175m per shift
A22: First operating and inspection (1.5 shifts) | C22: =1.5/C10 -> #DIV/0! | D22: 1.5 shifts
A23: Landing doors | C23: =C9/C10 -> #DIV/0! | D23: 1 landing door per shift per day
A24: Vinyl and travel
A25: LOP place drilling
A26: Cabin Interior assembly
A27: Electrical equipment
A28: Testing and commissioning
A29: Estimated Working Days | C29: =SUM(C16:C28) -> #DIV/0!
A31: Duration of 1 elevator intallation by month | C31: =C29/C11 -> #DIV/0!
A32: Number of Teams
A33: Qty. of Elevators
A35: Duration of all Elevators intallation by months | C35: =C31*C33/C32 -> #DIV/0!

Sheet L3 Info
A1: General Details / Installation Time
A2: Project NO. : | C2: DOC No.:
A3: Date: | B3: ____/___/_____ | C3: Serial NO. : | G3: Inputs
C4: REV NO. : | G4: Output
A6: Elevator General Data | C6: Value | D6: Remarks
A7: Elevator Name | C7: L3
A8: Total Height, m
A9: No. of Landing doors
A10: Number of shifts | D10: 1 OR 1.5
A11: Number of working day per Month | D11: 4 days off is mandatory safety wise for rest and relief
A12: No. of guiderails set (each set is 5m) | C12: =C8/5 -> 0 | D12: Each sets is consists of 2 CAR 5m guiderails, 2 CWT 5m guiderails, 3 brackets for each guiderails 12 by total
A13: No. of traction ropes | D13: The ropes quantity is drawn from motor specs
A15: Project Estimated time, working day | C15: Days | D15: Remarks
A16: Scaffolding | C16: =C8/(C10*20) -> #DIV/0! | D16: 20m per shift
A17: Jigs and nots
A18: Guiderails | C18: =(C8/(5*C10))+1 -> #DIV/0! | D18: 1 set per shift
A19: Motor and control panel | C19: =1.5/C10 -> #DIV/0! | D19: 1.5 shifts
A20: Cabin and counter weight frame (1.5 shifts) | C20: =1.5/C10 -> #DIV/0! | D20: 1.5 shifts
A21: Traction ropes | C21: =(2*C8*C13)/(C10*175) -> #DIV/0! | D21: 175m per shift
A22: First operating and inspection (1.5 shifts) | C22: =1.5/C10 -> #DIV/0! | D22: 1.5 shifts
A23: Landing doors | C23: =C9/C10 -> #DIV/0! | D23: 1 landing door per shift per day
A24: Vinyl and travel
A25: LOP place drilling
A26: Cabin Interior assembly
A27: Electrical equipment
A28: Testing and commissioning
A29: Estimated Working Days | C29: =SUM(C16:C28) -> #DIV/0!
A31: Duration of 1 elevator intallation by month | C31: =C29/C11 -> #DIV/0!
A32: Number of Teams
A33: Qty. of Elevators
A35: Duration of all Elevators intallation by months | C35: =C31*C33/C32 -> #DIV/0!

Sheet L4 Info
A1: General Details / Installation Time
A2: Project NO. : | C2: DOC No.:
A3: Date: | B3: ____/___/_____ | C3: Serial NO. : | G3: Inputs
C4: REV NO. : | G4: Output
A6: Elevator General Data | C6: Value | D6: Remarks
A7: Elevator Name | C7: L4
A8: Total Height, m
A9: No. of Landing doors
A10: Number of shifts | D10: 1 OR 1.5
A11: Number of working day per Month | D11: 4 days off is mandatory safety wise for rest and relief
A12: No. of guiderails set (each set is 5m) | C12: =C8/5 -> 0 | D12: Each sets is consists of 2 CAR 5m guiderails, 2 CWT 5m guiderails, 3 brackets for each guiderails 12 by total
A13: No. of traction ropes | D13: The ropes quantity is drawn from motor specs
A15: Project Estimated time, working day | C15: Days | D15: Remarks
A16: Scaffolding | C16: =C8/(C10*20) -> #DIV/0! | D16: 20m per shift
A17: Jigs and nots
A18: Guiderails | C18: =(C8/(5*C10))+1 -> #DIV/0! | D18: 1 set per shift
A19: Motor and control panel | C19: =1.5/C10 -> #DIV/0! | D19: 1.5 shifts
A20: Cabin and counter weight frame (1.5 shifts) | C20: =1.5/C10 -> #DIV/0! | D20: 1.5 shifts
A21: Traction ropes | C21: =(2*C8*C13)/(C10*175) -> #DIV/0! | D21: 175m per shift
A22: First operating and inspection (1.5 shifts) | C22: =1.5/C10 -> #DIV/0! | D22: 1.5 shifts
A23: Landing doors | C23: =C9/C10 -> #DIV/0! | D23: 1 landing door per shift per day
A24: Vinyl and travel
A25: LOP place drilling
A26: Cabin Interior assembly
A27: Electrical equipment
A28: Testing and commissioning
A29: Estimated Working Days | C29: =SUM(C16:C28) -> #DIV/0!
A31: Duration of 1 elevator intallation by month | C31: =C29/C11 -> #DIV/0!
A32: Number of Teams
A33: Qty. of Elevators
A35: Duration of all Elevators intallation by months | C35: =C31*C33/C32 -> #DIV/0!

Sheet L5 Info
A1: General Details / Installation Time
A2: Project NO. : | C2: DOC No.:
A3: Date: | B3: ____/___/_____ | C3: Serial NO. : | G3: Inputs
C4: REV NO. : | G4: Output
A6: Elevator General Data | C6: Value | D6: Remarks
A7: Elevator Name | C7: L5
A8: Total Height, m
A9: No. of Landing doors
A10: Number of shifts | D10: 1 OR 1.5
A11: Number of working day per Month | D11: 4 days off is mandatory safety wise for rest and relief
A12: No. of guiderails set (each set is 5m) | C12: =C8/5 -> 0 | D12: Each sets is consists of 2 CAR 5m guiderails, 2 CWT 5m guiderails, 3 brackets for each guiderails 12 by total
A13: No. of traction ropes | D13: The ropes quantity is drawn from motor specs
A15: Project Estimated time, working day | C15: Days | D15: Remarks
A16: Scaffolding | C16: =C8/(C10*20) -> #DIV/0! | D16: 20m per shift
A17: Jigs and nots
A18: Guiderails | C18: =(C8/(5*C10))+1 -> #DIV/0! | D18: 1 set per shift
A19: Motor and control panel | C19: =1.5/C10 -> #DIV/0! | D19: 1.5 shifts
A20: Cabin and counter weight frame (1.5 shifts) | C20: =1.5/C10 -> #DIV/0! | D20: 1.5 shifts
A21: Traction ropes | C21: =(2*C8*C13)/(C10*175) -> #DIV/0! | D21: 175m per shift
A22: First operating and inspection (1.5 shifts) | C22: =1.5/C10 -> #DIV/0! | D22: 1.5 shifts
A23: Landing doors | C23: =C9/C10 -> #DIV/0! | D23: 1 landing door per shift per day
A24: Vinyl and travel
A25: LOP place drilling
A26: Cabin Interior assembly
A27: Electrical equipment
A28: Testing and commissioning
A29: Estimated Working Days | C29: =SUM(C16:C28) -> #DIV/0!
A31: Duration of 1 elevator intallation by month | C31: =C29/C11 -> #DIV/0!
A32: Number of Teams
A33: Qty. of Elevators
A35: Duration of all Elevators intallation by months | C35: =C31*C33/C32 -> #DIV/0!

Sheet L1
A1: COST CALCULATION
B2: Project: | E2: DOC No.:
B3: Project NO. : | E3: Serial NO. :
B4: Date: | E4: REV NO. :
B6: SHARP Quotation Ref. Number:
B7: QUOTATION DATE:
B8: Elevator Name: | D8: L1
A11: No. | B11: Description | D11: Qty | E11: Rate | F11: Amount | I11: Input | J11: 1
A12: 1 | B12: FOB price Per Elevator | D12: 2 | E12: 8800 | F12: =D12*E12 -> 17600 | I12: Calculation | J12: 1
A13: 2 | B13: Banking Charge | C13: Banking Charge | D13: 0.05 | E13: =D12*E12 -> 17600 | F13: =D13*E13 -> 880 | I13: Output | J13: 1
A14: 3 | B14: Overhead (percentage of the FOB) | C14: Overhead (percentage of the FOB) | D14: 0.05 | E14: =D12*E12 -> 17600 | F14: =D14*E14 -> 880
A15: 4 | B15: Free Maintenance (percentage of the CIF) | C15: Free Maintenance (percentage of the CIF) | D15: 0.02 | E15: =F12+F13 -> 18480 | F15: =D15*E15 -> 369.6
A16: 5 | B16: Local Materials | C16: Local Materials | D16: =D12 -> 2 | E16: 500 | F16: =D16*E16 -> 1000
A17: 6 | B17: Cranes | C17: Cranes | D17: =D12 -> 2 | F17: =D17*E17 -> 0
A18: 7 | B18: Forklifts | C18: Forklifts | D18: 0 | F18: =D18*E18 -> 0
A19: 8 | B19: Scaffolding | C19: Scaffolding | D19: =D12 -> 2 | E19: 750 | F19: =D19*E19 -> 1500
A20: 9 | B20: Civil Works | C20: Civil Works | D20: =D12 -> 2 | F20: =D20*E20 -> 0
A21: 10 | B21: Metal Separating Beams | C21: Metal Separating Beams | D21: =D12 -> 2 | F21: =D21*E21 -> 0
A22: 11 | B22: Power Source / generator | C22: Power Source / generator | D22: =D12 -> 2 | F22: =D22*E22 -> 0
A23: 12 | B23: Power Cables | C23: Power Cables | D23: =D12 -> 2 | F23: =D23*E23 -> 0
A24: 13 | B24: Installation by Other Technicians | C24: Installation by Other Technicians | D24: =D12 -> 2 | F24: =D24*E24 -> 0
A25: 14 | B25: Installation by local staff | C25: Installation by local staff | D25: =D12 -> 2 | E25: 2000 | F25: =D25*E25 -> 4000
A26: 15 | B26: Accommodation | C26: Accommodation | D26: =D12 -> 2 | E26: 0 | F26: =D26*E26 -> 0
A27: 16 | B27: Travel Expenses | C27: Travel Expenses | D27: =D12 -> 2 | E27: 0 | F27: =D27*E27 -> 0
A28: 17 | B28: Bid Bond | C28: Bid Bond | D28: =D12 -> 2 | E28: 0 | F28: =D28*E28 -> 0
A29: 18 | B29: Performance Bond | C29: Performance Bond | D29: =D12 -> 2 | E29: 0 | F29: =D29*E29 -> 0
A30: 19 | B30: Design & Study (3% In Case) | C30: Design & Study (3% In Case) | D30: 0 | E30: =F12 -> 17600 | F30: =D30*E30 -> 0
A31: 20 | B31: Any Additional requirements by client | C31: Any Additional requirements by client | D31: 0.01 | E31: 0 | F31: =D31*E31 -> 0
C33: Total Cost of Elevators: | E33: =SUM(F12:F31) -> 26229.6
C34: Cost per one Elevator: | E34: =IF(E33>0,E33/D12,0) -> 13114.8

Sheet L2
A1: COST CALCULATION
B2: Project: | E2: DOC No.:
B3: Project NO. : | E3: Serial NO. :
B4: Date: | E4: REV NO. :
B6: SHARP Quotation Ref. Number:
B7: QUOTATION DATE:
B8: Elevator Name: | D8: L2
A11: No. | B11: Description | D11: Qty | E11: Rate | F11: Amount | I11: Input | J11: 1
A12: 1 | B12: FOB price Per Elevator | D12: 0 | E12: 0 | F12: =D12*E12 -> 0 | I12: Calculation | J12: 1
A13: 2 | B13: Banking Charge | C13: Banking Charge | D13: 0.05 | E13: =D12*E12 -> 0 | F13: =D13*E13 -> 0 | I13: Output | J13: 1
A14: 3 | B14: Overhead (percentage of the FOB) | C14: Overhead (percentage of the FOB) | D14: 0.05 | E14: =D12*E12 -> 0 | F14: =D14*E14 -> 0
A15: 4 | B15: Free Maintenance (percentage of the CIF) | C15: Free Maintenance (percentage of the CIF) | D15: 0.02 | E15: =F12+F13 -> 0 | F15: =D15*E15 -> 0
A16: 5 | B16: Local Materials | C16: Local Materials | D16: =D12 -> 0 | F16: =D16*E16 -> 0
A17: 6 | B17: Cranes | C17: Cranes | D17: =D12 -> 0 | F17: =D17*E17 -> 0
A18: 7 | B18: Forklifts | C18: Forklifts | D18: 0 | F18: =D18*E18 -> 0
A19: 8 | B19: Scaffolding | C19: Scaffolding | D19: =D12 -> 0 | F19: =D19*E19 -> 0
A20: 9 | B20: Civil Works | C20: Civil Works | D20: =D12 -> 0 | F20: =D20*E20 -> 0
A21: 10 | B21: Metal Separating Beams | C21: Metal Separating Beams | D21: =D12 -> 0 | F21: =D21*E21 -> 0
A22: 11 | B22: Power Source / generator | C22: Power Source / generator | D22: =D12 -> 0 | F22: =D22*E22 -> 0
A23: 12 | B23: Power Cables | C23: Power Cables | D23: =D12 -> 0 | F23: =D23*E23 -> 0
A24: 13 | B24: Installation by Other Technicians | C24: Installation by Other Technicians | D24: =D12 -> 0 | F24: =D24*E24 -> 0
A25: 14 | B25: Installation by local staff | C25: Installation by local staff | D25: =D12 -> 0 | F25: =D25*E25 -> 0
A26: 15 | B26: Accommodation | C26: Accommodation | D26: =D12 -> 0 | F26: =D26*E26 -> 0
A27: 16 | B27: Travel Expenses | C27: Travel Expenses | D27: =D12 -> 0 | E27: 0 | F27: =D27*E27 -> 0
A28: 17 | B28: Bid Bond | C28: Bid Bond | D28: =D12 -> 0 | E28: 0 | F28: =D28*E28 -> 0
A29: 18 | B29: Performance Bond | C29: Performance Bond | D29: =D12 -> 0 | E29: 0 | F29: =D29*E29 -> 0
A30: 19 | B30: Design & Study (3% In Case) | C30: Design & Study (3% In Case) | D30: 0 | E30: =F12 -> 0 | F30: =D30*E30 -> 0
A31: 20 | B31: Any Additional requirements by client | C31: Any Additional requirements by client | D31: 0.01 | E31: 0 | F31: =D31*E31 -> 0
C33: Total Cost of Elevators: | E33: =SUM(F12:F31) -> 0
C34: Cost per one Elevator: | E34: =IF(E33>0,E33/D12,0) -> 0

Sheet L3
A1: COST CALCULATION
B2: Project: | E2: DOC No.:
B3: Project NO. : | E3: Serial NO. :
B4: Date: | E4: REV NO. :
B6: SHARP Quotation Ref. Number:
B7: QUOTATION DATE:
B8: Elevator Name: | D8: L3
A11: No. | B11: Description | D11: Qty | E11: Rate | F11: Amount | I11: Input | J11: 1
A12: 1 | B12: FOB price Per Elevator | D12: 0 | E12: 0 | F12: =D12*E12 -> 0 | I12: Calculation | J12: 1
A13: 2 | B13: Banking Charge | C13: Banking Charge | D13: 0.05 | E13: =D12*E12 -> 0 | F13: =D13*E13 -> 0 | I13: Output | J13: 1
A14: 3 | B14: Overhead (percentage of the FOB) | C14: Overhead (percentage of the FOB) | D14: 0.05 | E14: =D12*E12 -> 0 | F14: =D14*E14 -> 0
A15: 4 | B15: Free Maintenance (percentage of the CIF) | C15: Free Maintenance (percentage of the CIF) | D15: 0.02 | E15: =F12+F13 -> 0 | F15: =D15*E15 -> 0
A16: 5 | B16: Local Materials | C16: Local Materials | D16: =D12 -> 0 | F16: =D16*E16 -> 0
A17: 6 | B17: Cranes | C17: Cranes | D17: =D12 -> 0 | F17: =D17*E17 -> 0
A18: 7 | B18: Forklifts | C18: Forklifts | D18: 0 | F18: =D18*E18 -> 0
A19: 8 | B19: Scaffolding | C19: Scaffolding | D19: =D12 -> 0 | F19: =D19*E19 -> 0
A20: 9 | B20: Civil Works | C20: Civil Works | D20: =D12 -> 0 | F20: =D20*E20 -> 0
A21: 10 | B21: Metal Separating Beams | C21: Metal Separating Beams | D21: =D12 -> 0 | F21: =D21*E21 -> 0
A22: 11 | B22: Power Source / generator | C22: Power Source / generator | D22: =D12 -> 0 | F22: =D22*E22 -> 0
A23: 12 | B23: Power Cables | C23: Power Cables | D23: =D12 -> 0 | F23: =D23*E23 -> 0
A24: 13 | B24: Installation by Other Technicians | C24: Installation by Other Technicians | D24: =D12 -> 0 | F24: =D24*E24 -> 0
A25: 14 | B25: Installation by local staff | C25: Installation by local staff | D25: =D12 -> 0 | F25: =D25*E25 -> 0
A26: 15 | B26: Accommodation | C26: Accommodation | D26: =D12 -> 0 | F26: =D26*E26 -> 0
A27: 16 | B27: Travel Expenses | C27: Travel Expenses | D27: =D12 -> 0 | F27: =D27*E27 -> 0
A28: 17 | B28: Bid Bond | C28: Bid Bond | D28: =D12 -> 0 | F28: =D28*E28 -> 0
A29: 18 | B29: Performance Bond | C29: Performance Bond | D29: =D12 -> 0 | F29: =D29*E29 -> 0
A30: 19 | B30: Design & Study (3% In Case) | C30: Design & Study (3% In Case) | D30: 0 | E30: =F12 -> 0 | F30: =D30*E30 -> 0
A31: 20 | B31: Any Additional requirements by client | C31: Any Additional requirements by client | D31: 0.01 | E31: 0 | F31: =D31*E31 -> 0
C33: Total Cost of Elevators: | E33: =SUM(F12:F31) -> 0
C34: Cost per one Elevator: | E34: =IF(E33>0,E33/D12,0) -> 0

Sheet L4
A1: COST CALCULATION
B2: Project: | E2: DOC No.:
B3: Project NO. : | E3: Serial NO. :
B4: Date: | E4: REV NO. :
B6: SHARP Quotation Ref. Number:
B7: QUOTATION DATE:
B8: Elevator Name: | D8: L4
A11: No. | B11: Description | D11: Qty | E11: Rate | F11: Amount | I11: Input | J11: 1
A12: 1 | B12: FOB price Per Elevator | D12: 0 | E12: 0 | F12: =D12*E12 -> 0 | I12: Calculation | J12: 1
A13: 2 | B13: Banking Charge | C13: Banking Charge | D13: 0.05 | E13: =D12*E12 -> 0 | F13: =D13*E13 -> 0 | I13: Output | J13: 1
A14: 3 | B14: Overhead (percentage of the FOB) | C14: Overhead (percentage of the FOB) | D14: 0.05 | E14: =D12*E12 -> 0 | F14: =D14*E14 -> 0
A15: 4 | B15: Free Maintenance (percentage of the CIF) | C15: Free Maintenance (percentage of the CIF) | D15: 0 | E15: =F12+F13 -> 0 | F15: =D15*E15 -> 0
A16: 5 | B16: Local Materials | C16: Local Materials | D16: =D12 -> 0 | F16: =D16*E16 -> 0
A17: 6 | B17: Cranes | C17: Cranes | D17: =D12 -> 0 | F17: =D17*E17 -> 0
A18: 7 | B18: Forklifts | C18: Forklifts | D18: 0 | F18: =D18*E18 -> 0
A19: 8 | B19: Scaffolding | C19: Scaffolding | D19: =D12 -> 0 | F19: =D19*E19 -> 0
A20: 9 | B20: Civil Works | C20: Civil Works | D20: =D12 -> 0 | F20: =D20*E20 -> 0
A21: 10 | B21: Metal Separating Beams | C21: Metal Separating Beams | D21: =D12 -> 0 | F21: =D21*E21 -> 0
A22: 11 | B22: Power Source / generator | C22: Power Source / generator | D22: =D12 -> 0 | F22: =D22*E22 -> 0
A23: 12 | B23: Power Cables | C23: Power Cables | D23: =D12 -> 0 | F23: =D23*E23 -> 0
A24: 13 | B24: Installation by Other Technicians | C24: Installation by Other Technicians | D24: =D12 -> 0 | F24: =D24*E24 -> 0
A25: 14 | B25: Installation by local staff | C25: Installation by local staff | D25: =D12 -> 0 | F25: =D25*E25 -> 0
A26: 15 | B26: Accommodation | C26: Accommodation | D26: =D12 -> 0 | F26: =D26*E26 -> 0
A27: 16 | B27: Travel Expenses | C27: Travel Expenses | D27: =D12 -> 0 | F27: =D27*E27 -> 0
A28: 17 | B28: Bid Bond | C28: Bid Bond | D28: =D12 -> 0 | F28: =D28*E28 -> 0
A29: 18 | B29: Performance Bond | C29: Performance Bond | D29: =D12 -> 0 | F29: =D29*E29 -> 0
A30: 19 | B30: Design & Study (3% In Case) | C30: Design & Study (3% In Case) | D30: 0 | E30: =F12 -> 0 | F30: =D30*E30 -> 0
A31: 20 | B31: Any Additional requirements by client | C31: Any Additional requirements by client | D31: 0.01 | E31: 0 | F31: =D31*E31 -> 0
C33: Total Cost of Elevators: | E33: =SUM(F12:F31) -> 0
C34: Cost per one Elevator: | E34: =IF(E33>0,E33/D12,0) -> 0

Sheet L5 Cost
A1: COST CALCULATION
B2: Project: | E2: DOC No.:
B3: Project NO. : | E3: Serial NO. :
B4: Date: | E4: REV NO. :
B6: SHARP Quotation Ref. Number:
B7: QUOTATION DATE:
B8: Elevator Name: | D8: L5
A11: No. | B11: Description | D11: Qty | E11: Rate | F11: Amount | I11: Input | J11: 1
A12: 1 | B12: FOB price Per Elevator | D12: 0 | E12: 0 | F12: =D12*E12 -> 0 | I12: Calculation | J12: 1
A13: 2 | B13: Banking Charge | C13: Banking Charge | D13: 0.05 | E13: =D12*E12 -> 0 | F13: =D13*E13 -> 0 | I13: Output | J13: 1
A14: 3 | B14: Overhead (percentage of the FOB) | C14: Overhead (percentage of the FOB) | D14: 0.05 | E14: =D12*E12 -> 0 | F14: =D14*E14 -> 0
A15: 4 | B15: Free Maintenance (percentage of the CIF) | C15: Free Maintenance (percentage of the CIF) | D15: 0.05 | E15: =F12+F13 -> 0 | F15: =D15*E15 -> 0
A16: 5 | B16: Local Materials | C16: Local Materials | D16: =D12 -> 0 | F16: =D16*E16 -> 0
A17: 6 | B17: Cranes | C17: Cranes | D17: =D12 -> 0 | F17: =D17*E17 -> 0
A18: 7 | B18: Forklifts | C18: Forklifts | D18: 0 | F18: =D18*E18 -> 0
A19: 8 | B19: Scaffolding | C19: Scaffolding | D19: =D12 -> 0 | F19: =D19*E19 -> 0
A20: 9 | B20: Civil Works | C20: Civil Works | D20: =D12 -> 0 | F20: =D20*E20 -> 0
A21: 10 | B21: Metal Separating Beams | C21: Metal Separating Beams | D21: =D12 -> 0 | F21: =D21*E21 -> 0
A22: 11 | B22: Power Source / generator | C22: Power Source / generator | D22: =D12 -> 0 | F22: =D22*E22 -> 0
A23: 12 | B23: Power Cables | C23: Power Cables | D23: =D12 -> 0 | F23: =D23*E23 -> 0
A24: 13 | B24: Installation by Other Technicians | C24: Installation by Other Technicians | D24: =D12 -> 0 | F24: =D24*E24 -> 0
A25: 14 | B25: Installation by local staff | C25: Installation by local staff | D25: =D12 -> 0 | F25: =D25*E25 -> 0
A26: 15 | B26: Accommodation | C26: Accommodation | D26: =D12 -> 0 | F26: =D26*E26 -> 0
A27: 16 | B27: Travel Expenses | C27: Travel Expenses | D27: =D12 -> 0 | F27: =D27*E27 -> 0
A28: 17 | B28: Bid Bond | C28: Bid Bond | D28: =D12 -> 0 | F28: =D28*E28 -> 0
A29: 18 | B29: Performance Bond | C29: Performance Bond | D29: =D12 -> 0 | F29: =D29*E29 -> 0
A30: 19 | B30: Design & Study (3% In Case) | C30: Design & Study (3% In Case) | D30: 0 | E30: =F12 -> 0 | F30: =D30*E30 -> 0
A31: 20 | B31: Any Additional requirements by client | C31: Any Additional requirements by client | D31: 0.01 | E31: 0 | F31: =D31*E31 -> 0
C33: Total Cost of Elevators: | E33: =SUM(F12:F31) -> 0
C34: Cost per one Elevator: | E34: =IF(E33>0,E33/D12,0) -> 0

Sheet E1
A1: COST CALCULATION
B2: Project: | E2: DOC No.:
B3: Project NO. : | E3: Serial NO. :
B4: Date: | E4: REV NO. :
B6: SHARP Quotation Ref. Number:
B7: QUOTATION DATE:
B8: Escalator Name: | D8: E1
A11: No. | B11: Description | D11: Qty | E11: Rate | F11: Amount | I11: Input | J11: 1
A12: 1 | B12: FOB price Per Elevator | D12: 0 | E12: 1000 | F12: =D12*E12 -> 0 | I12: Calculation | J12: 1
A13: 2 | B13: Banking Charge | C13: Banking Charge | D13: 0.05 | E13: =D12*E12 -> 0 | F13: =D13*E13 -> 0 | I13: Output | J13: 1
A14: 3 | B14: Overhead (percentage of the FOB) | C14: Overhead (percentage of the FOB) | D14: 0.05 | E14: =D12*E12 -> 0 | F14: =D14*E14 -> 0
A15: 4 | B15: Free Maintenance (percentage of the CIF) | C15: Free Maintenance (percentage of the CIF) | D15: 0.05 | E15: =F12+F13 -> 0 | F15: =D15*E15 -> 0
A16: 5 | B16: Local Materials | C16: Local Materials | D16: =D12 -> 0 | F16: =D16*E16 -> 0
A17: 6 | B17: Cranes | C17: Cranes | D17: =D12 -> 0 | F17: =D17*E17 -> 0
A18: 7 | B18: Forklifts | C18: Forklifts | D18: 0 | F18: =D18*E18 -> 0
A19: 8 | B19: Scaffolding | C19: Scaffolding | D19: =D12 -> 0 | F19: =D19*E19 -> 0
A20: 9 | B20: Civil Works | C20: Civil Works | D20: =D12 -> 0 | F20: =D20*E20 -> 0
A21: 10 | B21: Metal Separating Beams | C21: Metal Separating Beams | D21: =D12 -> 0 | F21: =D21*E21 -> 0
A22: 11 | B22: Power Source / generator | C22: Power Source / generator | D22: =D12 -> 0 | F22: =D22*E22 -> 0
A23: 12 | B23: Power Cables | C23: Power Cables | D23: =D12 -> 0 | F23: =D23*E23 -> 0
A24: 13 | B24: Installation by Other Technicians | C24: Installation by Other Technicians | D24: =D12 -> 0 | F24: =D24*E24 -> 0
A25: 14 | B25: Installation by local staff | C25: Installation by local staff | D25: =D12 -> 0 | F25: =D25*E25 -> 0
A26: 15 | B26: Accommodation | C26: Accommodation | D26: =D12 -> 0 | F26: =D26*E26 -> 0
A27: 16 | B27: Travel Expenses | C27: Travel Expenses | D27: =D12 -> 0 | F27: =D27*E27 -> 0
A28: 17 | B28: Bid Bond | C28: Bid Bond | D28: =D12 -> 0 | F28: =D28*E28 -> 0
A29: 18 | B29: Performance Bond | C29: Performance Bond | D29: =D12 -> 0 | F29: =D29*E29 -> 0
A30: 19 | B30: Design & Study (3% In Case) | C30: Design & Study (3% In Case) | D30: 0 | E30: =F12 -> 0 | F30: =D30*E30 -> 0
A31: 20 | B31: Any Additional requirements by client | C31: Any Additional requirements by client | D31: 0.01 | E31: 0 | F31: =D31*E31 -> 0
C33: Total Cost of Elevators: | E33: =SUM(F12:F31) -> 0
C34: Cost per one Elevator: | E34: =IF(E33>0,E33/D12,0) -> 0

Sheet E2
A1: COST CALCULATION
B2: Project: | E2: DOC No.:
B3: Project NO. : | E3: Serial NO. :
B4: Date: | E4: REV NO. :
B6: SHARP Quotation Ref. Number:
B7: QUOTATION DATE:
B8: Escalator Name: | D8: E2
A11: No. | B11: Description | D11: Qty | E11: Rate | F11: Amount | I11: Input | J11: 1
A12: 1 | B12: FOB price Per Elevator | D12: 0 | E12: 1000 | F12: =D12*E12 -> 0 | I12: Calculation | J12: 1
A13: 2 | B13: Banking Charge | C13: Banking Charge | D13: 0.05 | E13: =D12*E12 -> 0 | F13: =D13*E13 -> 0 | I13: Output | J13: 1
A14: 3 | B14: Overhead (percentage of the FOB) | C14: Overhead (percentage of the FOB) | D14: 0.05 | E14: =D12*E12 -> 0 | F14: =D14*E14 -> 0
A15: 4 | B15: Free Maintenance (percentage of the CIF) | C15: Free Maintenance (percentage of the CIF) | D15: 0.05 | E15: =F12+F13 -> 0 | F15: =D15*E15 -> 0
A16: 5 | B16: Local Materials | C16: Local Materials | D16: =D12 -> 0 | F16: =D16*E16 -> 0
A17: 6 | B17: Cranes | C17: Cranes | D17: =D12 -> 0 | F17: =D17*E17 -> 0
A18: 7 | B18: Forklifts | C18: Forklifts | D18: 0 | F18: =D18*E18 -> 0
A19: 8 | B19: Scaffolding | C19: Scaffolding | D19: =D12 -> 0 | F19: =D19*E19 -> 0
A20: 9 | B20: Civil Works | C20: Civil Works | D20: =D12 -> 0 | F20: =D20*E20 -> 0
A21: 10 | B21: Metal Separating Beams | C21: Metal Separating Beams | D21: =D12 -> 0 | F21: =D21*E21 -> 0
A22: 11 | B22: Power Source / generator | C22: Power Source / generator | D22: =D12 -> 0 | F22: =D22*E22 -> 0
A23: 12 | B23: Power Cables | C23: Power Cables | D23: =D12 -> 0 | F23: =D23*E23 -> 0
A24: 13 | B24: Installation by Other Technicians | C24: Installation by Other Technicians | D24: =D12 -> 0 | F24: =D24*E24 -> 0
A25: 14 | B25: Installation by local staff | C25: Installation by local staff | D25: =D12 -> 0 | F25: =D25*E25 -> 0
A26: 15 | B26: Accommodation | C26: Accommodation | D26: =D12 -> 0 | F26: =D26*E26 -> 0
A27: 16 | B27: Travel Expenses | C27: Travel Expenses | D27: =D12 -> 0 | F27: =D27*E27 -> 0
A28: 17 | B28: Bid Bond | C28: Bid Bond | D28: =D12 -> 0 | F28: =D28*E28 -> 0
A29: 18 | B29: Performance Bond | C29: Performance Bond | D29: =D12 -> 0 | F29: =D29*E29 -> 0
A30: 19 | B30: Design & Study (3% In Case) | C30: Design & Study (3% In Case) | D30: 0 | E30: =F12 -> 0 | F30: =D30*E30 -> 0
A31: 20 | B31: Any Additional requirements by client | C31: Any Additional requirements by client | D31: 0.01 | E31: 0 | F31: =D31*E31 -> 0
C33: Total Cost of Elevators: | E33: =SUM(F12:F31) -> 0
C34: Cost per one Elevator: | E34: =IF(E33>0,E33/D12,0) -> 0

Sheet M1
A1: COST CALCULATION
B2: Project: | E2: DOC No.:
B3: Project NO. : | E3: Serial NO. :
B4: Date: | E4: REV NO. :
B6: SHARP Quotation Ref. Number:
B7: QUOTATION DATE:
B8: Moving Walk Name: | D8: M1
A11: No. | B11: Description | D11: Qty | E11: Rate | F11: Amount | I11: Input | J11: 1
A12: 1 | B12: FOB price Per Elevator | D12: 0 | E12: 1000 | F12: =D12*E12 -> 0 | I12: Calculation | J12: 1
A13: 2 | B13: Banking Charge | C13: Banking Charge | D13: 0.05 | E13: =D12*E12 -> 0 | F13: =D13*E13 -> 0 | I13: Output | J13: 1
A14: 3 | B14: Overhead (percentage of the FOB) | C14: Overhead (percentage of the FOB) | D14: 0.05 | E14: =D12*E12 -> 0 | F14: =D14*E14 -> 0
A15: 4 | B15: Free Maintenance (percentage of the CIF) | C15: Free Maintenance (percentage of the CIF) | D15: 0.05 | E15: =F12+F13 -> 0 | F15: =D15*E15 -> 0
A16: 5 | B16: Local Materials | C16: Local Materials | D16: =D12 -> 0 | F16: =D16*E16 -> 0
A17: 6 | B17: Cranes | C17: Cranes | D17: =D12 -> 0 | F17: =D17*E17 -> 0
A18: 7 | B18: Forklifts | C18: Forklifts | D18: 0 | F18: =D18*E18 -> 0
A19: 8 | B19: Scaffolding | C19: Scaffolding | D19: =D12 -> 0 | F19: =D19*E19 -> 0
A20: 9 | B20: Civil Works | C20: Civil Works | D20: =D12 -> 0 | F20: =D20*E20 -> 0
A21: 10 | B21: Metal Separating Beams | C21: Metal Separating Beams | D21: =D12 -> 0 | F21: =D21*E21 -> 0
A22: 11 | B22: Power Source / generator | C22: Power Source / generator | D22: =D12 -> 0 | F22: =D22*E22 -> 0
A23: 12 | B23: Power Cables | C23: Power Cables | D23: =D12 -> 0 | F23: =D23*E23 -> 0
A24: 13 | B24: Installation by Other Technicians | C24: Installation by Other Technicians | D24: =D12 -> 0 | F24: =D24*E24 -> 0
A25: 14 | B25: Installation by local staff | C25: Installation by local staff | D25: =D12 -> 0 | F25: =D25*E25 -> 0
A26: 15 | B26: Accommodation | C26: Accommodation | D26: =D12 -> 0 | F26: =D26*E26 -> 0
A27: 16 | B27: Travel Expenses | C27: Travel Expenses | D27: =D12 -> 0 | F27: =D27*E27 -> 0
A28: 17 | B28: Bid Bond | C28: Bid Bond | D28: =D12 -> 0 | F28: =D28*E28 -> 0
A29: 18 | B29: Performance Bond | C29: Performance Bond | D29: =D12 -> 0 | F29: =D29*E29 -> 0
A30: 19 | B30: Design & Study (3% In Case) | C30: Design & Study (3% In Case) | D30: 0 | E30: =F12 -> 0 | F30: =D30*E30 -> 0
A31: 20 | B31: Any Additional requirements by client | C31: Any Additional requirements by client | D31: 0.01 | E31: 0 | F31: =D31*E31 -> 0
C33: Total Cost of Elevators: | E33: =SUM(F12:F31) -> 0
C34: Cost per one Elevator: | E34: =IF(E33>0,E33/D12,0) -> 0

Sheet M2
A1: COST CALCULATION
B2: Project: | E2: DOC No.:
B3: Project NO. : | E3: Serial NO. :
B4: Date: | E4: REV NO. :
B6: SHARP Quotation Ref. Number:
B7: QUOTATION DATE:
B8: Moving Walk Name: | D8: M2
A11: No. | B11: Description | D11: Qty | E11: Rate | F11: Amount | I11: Input | J11: 1
A12: 1 | B12: FOB price Per Elevator | D12: 0 | E12: 1000 | F12: =D12*E12 -> 0 | I12: Calculation | J12: 1
A13: 2 | B13: Banking Charge | C13: Banking Charge | D13: 0.05 | E13: =D12*E12 -> 0 | F13: =D13*E13 -> 0 | I13: Output | J13: 1
A14: 3 | B14: Overhead (percentage of the FOB) | C14: Overhead (percentage of the FOB) | D14: 0.05 | E14: =D12*E12 -> 0 | F14: =D14*E14 -> 0
A15: 4 | B15: Free Maintenance (percentage of the CIF) | C15: Free Maintenance (percentage of the CIF) | D15: 0.05 | E15: =F12+F13 -> 0 | F15: =D15*E15 -> 0
A16: 5 | B16: Local Materials | C16: Local Materials | D16: =D12 -> 0 | F16: =D16*E16 -> 0
A17: 6 | B17: Cranes | C17: Cranes | D17: =D12 -> 0 | F17: =D17*E17 -> 0
A18: 7 | B18: Forklifts | C18: Forklifts | D18: 0 | F18: =D18*E18 -> 0
A19: 8 | B19: Scaffolding | C19: Scaffolding | D19: =D12 -> 0 | F19: =D19*E19 -> 0
A20: 9 | B20: Civil Works | C20: Civil Works | D20: =D12 -> 0 | F20: =D20*E20 -> 0
A21: 10 | B21: Metal Separating Beams | C21: Metal Separating Beams | D21: =D12 -> 0 | F21: =D21*E21 -> 0
A22: 11 | B22: Power Source / generator | C22: Power Source / generator | D22: =D12 -> 0 | F22: =D22*E22 -> 0
A23: 12 | B23: Power Cables | C23: Power Cables | D23: =D12 -> 0 | F23: =D23*E23 -> 0
A24: 13 | B24: Installation by Other Technicians | C24: Installation by Other Technicians | D24: =D12 -> 0 | F24: =D24*E24 -> 0
A25: 14 | B25: Installation by local staff | C25: Installation by local staff | D25: =D12 -> 0 | F25: =D25*E25 -> 0
A26: 15 | B26: Accommodation | C26: Accommodation | D26: =D12 -> 0 | F26: =D26*E26 -> 0
A27: 16 | B27: Travel Expenses | C27: Travel Expenses | D27: =D12 -> 0 | F27: =D27*E27 -> 0
A28: 17 | B28: Bid Bond | C28: Bid Bond | D28: =D12 -> 0 | F28: =D28*E28 -> 0
A29: 18 | B29: Performance Bond | C29: Performance Bond | D29: =D12 -> 0 | F29: =D29*E29 -> 0
A30: 19 | B30: Design & Study (3% In Case) | C30: Design & Study (3% In Case) | D30: 0 | E30: =F12 -> 0 | F30: =D30*E30 -> 0
A31: 20 | B31: Any Additional requirements by client | C31: Any Additional requirements by client | D31: 0.01 | E31: 0 | F31: =D31*E31 -> 0
C33: Total Cost of Elevators: | E33: =SUM(F12:F31) -> 0
C34: Cost per one Elevator: | E34: =IF(E33>0,E33/D12,0) -> 0

Sheet Proposed Price
A1: FINAL PRICE CALCULATION
B2: Project: | E2: DOC No.:
B3: Project NO. : | E3: Serial NO. :
B4: Date: | E4: REV NO. :
A6: Cost of Units Without Customes and Shipping
A7: No. | B7: Description | C7: Qty | D7: Unit Price | E7: Amount | F7: Remarks
A8: 1 | B8: Al thuraya Tower | C8: ='L1'!D12 -> 2 | D8: ='L1'!E34 -> 13114.8 | E8: =C8*D8 -> 26229.6
A9: 2 | C9: ='L2'!D12 -> 0 | D9: ='L2'!E34 -> 0 | E9: =C9*D9 -> 0
A10: 3 | C10: ='L3'!D12 -> 0 | D10: ='L3'!E34 -> 0 | E10: =C10*D10 -> 0
A11: 4 | C11: ='L4'!D12 -> 0 | D11: ='L4'!E34 -> 0 | E11: =C11*D11 -> 0
A12: 5 | B12: L5 | C12: ='L5 Cost'!D12 -> 0 | D12: ='L5 Cost'!E34 -> 0 | E12: =C12*D12 -> 0
A13: 6 | B13: E1 | C13: ='E1'!D12 -> 0 | D13: ='E1'!E34 -> 0 | E13: =C13*D13 -> 0
A14: 7 | B14: E2 | C14: ='E2'!D12 -> 0 | D14: ='E2'!E34 -> 0 | E14: =C14*D14 -> 0
A15: 8 | B15: M1 | C15: ='M1'!D12 -> 0 | D15: ='M1'!E34 -> 0 | E15: =C15*D15 -> 0
A16: 9 | B16: M2 | C16: ='M2'!D12 -> 0 | D16: ='M2'!E34 -> 0 | E16: =C16*D16 -> 0
A17: 10 | B17: Total Cost of all Elevators Without Customs | C17: - | D17: - | E17: =SUM(E8:E16) -> 26229.6
A19: Price of Units After Profit Without Customs
A20: No. | B20: Description | C20: Percentage | D20: Unit Price | E20: Amount | F20: Remarks
A21: 11 | B21: Al thuraya Tower | C21: 0.3 | D21: =D8/(1-C21) -> 18735.429 | E21: =E8/(1-C21) -> 37470.857
A22: 12 | C22: 0.3 | D22: =D9/(1-C22) -> 0 | E22: =E9/(1-C22) -> 0
A23: 13 | C23: 0.28 | D23: =D10/(1-C23) -> 0 | E23: =E10/(1-C23) -> 0
A24: 14 | C24: 0.2 | D24: =D11/(1-C24) -> 0 | E24: =E11/(1-C24) -> 0
A25: 15 | B25: L5 | C25: 0.35 | D25: =D12/(1-C25) -> 0 | E25: =E12/(1-C25) -> 0
A26: 16 | B26: E1 | C26: 0.3 | D26: =D13/(1-C26) -> 0 | E26: =E13/(1-C26) -> 0
A27: 17 | B27: E2 | C27: 0.3 | D27: =D14/(1-C27) -> 0 | E27: =E14/(1-C27) -> 0
A28: 18 | B28: M1 | C28: 0.3 | D28: =D15/(1-C28) -> 0 | E28: =E15/(1-C28) -> 0
A29: 19 | B29: M2 | C29: 0.3 | D29: =D16/(1-C29) -> 0 | E29: =E16/(1-C29) -> 0
A30: 20 | B30: Total Price After Profit Without Customs | C30: - | D30: - | E30: =SUM(E21:E29) -> 37470.857
A32: Net Profit of Units
A33: No. | B33: Description | C33: Qty | D33: Unit Price | E33: Amount | F33: Remarks
A34: 21 | B34: Al thuraya Tower | C34: =C8 -> 2 | D34: =D21-D8 -> 5620.6286 | E34: =E21-E8 -> 11241.257
A35: 22 | C35: =C9 -> 0 | D35: =D22-D9 -> 0 | E35: =E22-E9 -> 0
A36: 23 | C36: =C10 -> 0 | D36: =D23-D10 -> 0 | E36: =E23-E10 -> 0
A37: 24 | C37: =C11 -> 0 | D37: =D24-D11 -> 0 | E37: =E24-E11 -> 0
A38: 25 | B38: L5 | C38: =C12 -> 0 | D38: =D25-D12 -> 0 | E38: =E25-E12 -> 0
A39: 26 | B39: E1 | C39: =C13 -> 0 | D39: =D26-D13 -> 0 | E39: =E26-E13 -> 0
A40: 27 | B40: E2 | C40: =C14 -> 0 | D40: =D27-D14 -> 0 | E40: =E27-E14 -> 0
A41: 28 | B41: M1 | C41: =C15 -> 0 | D41: =D28-D15 -> 0 | E41: =E28-E15 -> 0
A42: 29 | B42: M2 | C42: =C16 -> 0 | D42: =D29-D16 -> 0 | E42: =E29-E16 -> 0
A43: 30 | B43: Total Net Profit | C43: - | D43: - | E43: =E30-E17 -> 11241.257
...

Sheet Discounted Price
A1: DISCOUNTED COST CALCULATION
B2: Project: | E2: DOC No.:
B3: Project NO. : | E3: Serial NO. :
B4: Date: | E4: REV NO. :
A6: DISCOUNTED PRICE
A7: No. | B7: Description | C7: Percentage | D7: Unit Price | E7: Amount | F7: Remarks
A8: 1 | B8: L1 | C8: 0.05 | D8: ='Proposed Price'!D63*(1-C8) -> 25735.429 | E8: ='Proposed Price'!E63*(1-C8) -> 51470.857 | H8: Legend
A9: 2 | B9: L2 | C9: 0.05 | D9: ='Proposed Price'!D64*(1-C9) -> #DIV/0! | E9: ='Proposed Price'!E64*(1-C9) -> 0 | H9: Input | I9: 1
A10: 3 | B10: L3 | C10: 0.05 | D10: ='Proposed Price'!D65*(1-C10) -> #DIV/0! | E10: ='Proposed Price'!E65*(1-C10) -> 0 | H10: Calculation | I10: 1
A11: 4 | B11: L4 | C11: 0.05 | D11: ='Proposed Price'!D66*(1-C11) -> #DIV/0! | E11: ='Proposed Price'!E66*(1-C11) -> 0 | H11: Output | I11: 1
A12: 5 | B12: L5 | C12: 0.05 | D12: ='Proposed Price'!D67*(1-C12) -> #DIV/0! | E12: ='Proposed Price'!E67*(1-C12) -> 0
A13: 6 | B13: E1 | C13: 0.05 | D13: ='Proposed Price'!D68*(1-C13) -> #DIV/0! | E13: ='Proposed Price'!E68*(1-C13) -> 0
A14: 7 | B14: E2 | C14: 0.05 | D14: ='Proposed Price'!D69*(1-C14) -> #DIV/0! | E14: ='Proposed Price'!E69*(1-C14) -> 0
A15: 8 | B15: M1 | C15: 0.05 | D15: ='Proposed Price'!D70*(1-C15) -> #DIV/0! | E15: ='Proposed Price'!E70*(1-C15) -> 0
A16: 9 | B16: M2 | C16: 0.05 | D16: ='Proposed Price'!D71*(1-C16) -> #DIV/0! | E16: ='Proposed Price'!E71*(1-C16) -> 0
A17: 10 | B17: Total Discounted Price: | E17: =SUM(E8:E16) -> 51470.857
A19: NEW INCOME TAX
A20: No. | B20: Description | C20: Percentage | D20: Unit Price | E20: Amount | F20: Remarks
A21: 11 | B21: L1 | C21: ='Proposed Price'!C63 -> 0.05 | D21: =D8*C21 -> 1286.7714 | E21: =E8*C21 -> 2573.5429
A22: 12 | B22: L2 | C22: ='Proposed Price'!C64 -> 0.07 | D22: =D9*C22 -> #DIV/0! | E22: =E9*C22 -> 0
A23: 13 | B23: L3 | C23: ='Proposed Price'!C65 -> 0.07 | D23: =D10*C23 -> #DIV/0! | E23: =E10*C23 -> 0
A24: 14 | B24: L4 | C24: ='Proposed Price'!C66 -> 0.05 | D24: =D11*C24 -> #DIV/0! | E24: =E11*C24 -> 0
A25: 15 | B25: L5 | C25: ='Proposed Price'!C67 -> 0.05 | D25: =D12*C25 -> #DIV/0! | E25: =E12*C25 -> 0
A26: 16 | B26: E1 | C26: ='Proposed Price'!C68 -> 0.05 | D26: =D13*C26 -> #DIV/0! | E26: =E13*C26 -> 0
A27: 17 | B27: E2 | C27: ='Proposed Price'!C69 -> 0.05 | D27: =D14*C27 -> #DIV/0! | E27: =E14*C27 -> 0
A28: 18 | B28: M1 | C28: ='Proposed Price'!C70 -> 0.05 | D28: =D15*C28 -> #DIV/0! | E28: =E15*C28 -> 0
A29: 19 | B29: M2 | C29: ='Proposed Price'!C71 -> 0.05 | D29: =D16*C29 -> #DIV/0! | E29: =E16*C29 -> 0
A30: 20 | B30: Total Income Tax: | E30: =SUM(E21:E29) -> 2573.5429
A32: NEW NET PROFIT
A33: No. | B33: Description | C33: Qty | D33: Unit Price | E33: Amount | F33: Remarks
A34: 21 | B34: L1 | C34: ='Proposed Price'!C8 -> 2 | D34: =E34/C34 -> 7833.8571 | E34: =E8-E21-'Proposed Price'!E8-'Proposed Price'!$C$45/(SUM('Proposed Price'!$C$8:$C$16)) -> 15667.714
A35: 22 | B35: L2 | C35: ='Proposed Price'!C9 -> 0 | D35: =E35/C35 -> #DIV/0! | E35: =E9-E22-'Proposed Price'!E9-'Proposed Price'!$C$45/(SUM('Proposed Price'!$C$8:$C$16)) -> -7000
A36: 23 | B36: L3 | C36: ='Proposed Price'!C10 -> 0 | D36: =E36/C36 -> #DIV/0! | E36: =E10-E23-'Proposed Price'!E10-'Proposed Price'!$C$45/(SUM('Proposed Price'!$C$8:$C$16)) -> -7000
A37: 24 | B37: L4 | C37: ='Proposed Price'!C11 -> 0 | D37: =E37/C37 -> #DIV/0! | E37: =E11-E24-'Proposed Price'!E11-'Proposed Price'!$C$45/(SUM('Proposed Price'!$C$8:$C$16)) -> -7000
A38: 25 | B38: L5 | C38: ='Proposed Price'!C12 -> 0 | D38: =E38/C38 -> #DIV/0! | E38: =E12-E25-'Proposed Price'!E12-'Proposed Price'!$C$45/(SUM('Proposed Price'!$C$8:$C$16)) -> -7000
A39: 26 | B39: E1 | C39: ='Proposed Price'!C13 -> 0 | D39: =E39/C39 -> #DIV/0! | E39: =E13-E26-'Proposed Price'!E13-'Proposed Price'!$C$45/(SUM('Proposed Price'!$C$8:$C$16)) -> -7000
A40: 27 | B40: E2 | C40: ='Proposed Price'!C14 -> 0 | D40: =E40/C40 -> #DIV/0! | E40: =E14-E27-'Proposed Price'!E14-'Proposed Price'!$C$45/(SUM('Proposed Price'!$C$8:$C$16)) -> -7000
A41: 28 | B41: M1 | C41: ='Proposed Price'!C15 -> 0 | D41: =E41/C41 -> #DIV/0! | E41: =E15-E28-'Proposed Price'!E15-'Proposed Price'!$C$45/(SUM('Proposed Price'!$C$8:$C$16)) -> -7000
A42: 29 | B42: M2 | C42: ='Proposed Price'!C16 -> 0 | D42: =E42/C42 -> #DIV/0! | E42: =E16-E29-'Proposed Price'!E16-'Proposed Price'!$C$45/(SUM('Proposed Price'!$C$8:$C$16)) -> -7000
A43: 30 | B43: Total Net Profit: | E43: =E17-E30-'Proposed Price'!E17-'Proposed Price'!C45 -> 8667.7143
...
